Workbook
Name Rides: #REF!
Name Slicer_Request_Date__Month: #N/A
Name Slicer_Ride_Status: #N/A
Name Slicer_Ride_Type: #N/A
Name Timeline_Request_Date: #N/A

Sheet Overview 

Sheet Operations & Location Analysi

Sheet Driver & Customer Insights
O16: `

Sheet Details
N10: Driver ID | O10: total completed rides
C11: Hour | D11: requests Total | H11: Hour | I11: total rides cacelled | N11: ='Analysis 2 '!D4 -> 210 | O11: ='Analysis 2 '!E4 -> 136
C12: =Analysis!H9 -> 0 | D12: =Analysis!I9 -> 405 | H12: ='Analysis 2 '!A4 -> 0 | I12: ='Analysis 2 '!B4 -> 96 | N12: ='Analysis 2 '!D5 -> 225 | O12: ='Analysis 2 '!E5 -> 128
C13: =Analysis!H10 -> 1 | D13: =Analysis!I10 -> 392 | H13: ='Analysis 2 '!A5 -> 1 | I13: ='Analysis 2 '!B5 -> 88 | N13: ='Analysis 2 '!D6 -> 234 | O13: ='Analysis 2 '!E6 -> 126 | T13: Driver ID | U13: Total Miles covered | V13: Column1
C14: =Analysis!H11 -> 2 | D14: =Analysis!I11 -> 423 | H14: ='Analysis 2 '!A6 -> 2 | I14: ='Analysis 2 '!B6 -> 102 | N14: ='Analysis 2 '!D7 -> 256 | O14: ='Analysis 2 '!E7 -> 126 | T14: ='Analysis 2 '!J6 -> 213 | U14: ='Analysis 2 '!K6 -> 2138.03
C15: =Analysis!H12 -> 3 | D15: =Analysis!I12 -> 420 | H15: ='Analysis 2 '!A7 -> 3 | I15: ='Analysis 2 '!B7 -> 101 | N15: ='Analysis 2 '!D8 -> 240 | O15: ='Analysis 2 '!E8 -> 125 | T15: ='Analysis 2 '!J7 -> 225 | U15: ='Analysis 2 '!K7 -> 1896.53
C16: =Analysis!H13 -> 4 | D16: =Analysis!I13 -> 431 | H16: ='Analysis 2 '!A8 -> 4 | I16: ='Analysis 2 '!B8 -> 98 | N16: ='Analysis 2 '!D9 -> 211 | O16: ='Analysis 2 '!E9 -> 125 | T16: ='Analysis 2 '!J8 -> 240 | U16: ='Analysis 2 '!K8 -> 1856.26
C17: =Analysis!H14 -> 5 | D17: =Analysis!I14 -> 455 | H17: ='Analysis 2 '!A9 -> 5 | I17: ='Analysis 2 '!B9 -> 89 | N17: ='Analysis 2 '!D10 -> 217 | O17: ='Analysis 2 '!E10 -> 125 | T17: ='Analysis 2 '!J9 -> 230 | U17: ='Analysis 2 '!K9 -> 1837.49
C18: =Analysis!H15 -> 6 | D18: =Analysis!I15 -> 408 | H18: ='Analysis 2 '!A10 -> 6 | I18: ='Analysis 2 '!B10 -> 98 | N18: ='Analysis 2 '!D11 -> 230 | O18: ='Analysis 2 '!E11 -> 125 | T18: ='Analysis 2 '!J10 -> 227 | U18: ='Analysis 2 '!K10 -> 1826.38
C19: =Analysis!H16 -> 7 | D19: =Analysis!I16 -> 387 | H19: ='Analysis 2 '!A11 -> 7 | I19: ='Analysis 2 '!B11 -> 96 | N19: ='Analysis 2 '!D12 -> Grand Total | O19: ='Analysis 2 '!E12 -> 1016 | Q19: ='Analysis 2 '!G12 -> 234 | R19: ='Analysis 2 '!H12 -> 5553.4 | T19: ='Analysis 2 '!J11 -> 228 | U19: ='Analysis 2 '!K11 -> 1819.84 | X19: ='Analysis 2 '!M11 -> Brixton | Y19: ='Analysis 2 '!N11 -> 19919.85
C20: =Analysis!H17 -> 8 | D20: =Analysis!I17 -> 416 | H20: ='Analysis 2 '!A12 -> 8 | I20: ='Analysis 2 '!B12 -> 86 | N20: ='Analysis 2 '!D13 -> 0 | O20: ='Analysis 2 '!E13 -> 0 | Q20: ='Analysis 2 '!G13 -> 218 | R20: ='Analysis 2 '!H13 -> 5536.75 | T20: ='Analysis 2 '!J12 -> 248 | U20: ='Analysis 2 '!K12 -> 1796.18 | X20: ='Analysis 2 '!M12 -> Stratford | Y20: ='Analysis 2 '!N12 -> 19631.89
C21: =Analysis!H18 -> 9 | D21: =Analysis!I18 -> 427 | H21: ='Analysis 2 '!A13 -> 9 | I21: ='Analysis 2 '!B13 -> 101 | N21: ='Analysis 2 '!D14 -> 0 | O21: ='Analysis 2 '!E14 -> 0 | T21: ='Analysis 2 '!J13 -> 252 | U21: ='Analysis 2 '!K13 -> 1757.24 | X21: ='Analysis 2 '!M13 -> Waterloo | Y21: ='Analysis 2 '!N13 -> 19411.92
C22: =Analysis!H19 -> 10 | D22: =Analysis!I19 -> 454 | H22: ='Analysis 2 '!A14 -> 10 | I22: ='Analysis 2 '!B14 -> 105 | N22: ='Analysis 2 '!D15 -> 0 | O22: ='Analysis 2 '!E15 -> 0 | T22: ='Analysis 2 '!J14 -> 208 | U22: ='Analysis 2 '!K14 -> 1752.89 | X22: ='Analysis 2 '!M14 -> Canary Wharf | Y22: ='Analysis 2 '!N14 -> 19410.64
C23: =Analysis!H20 -> 11 | D23: =Analysis!I20 -> 403 | H23: ='Analysis 2 '!A15 -> 11 | I23: ='Analysis 2 '!B15 -> 81 | N23: ='Analysis 2 '!D16 -> 0 | O23: ='Analysis 2 '!E16 -> 0 | T23: ='Analysis 2 '!J15 -> 236 | U23: ='Analysis 2 '!K15 -> 1748.27 | X23: ='Analysis 2 '!M15 -> Elephant And Castle | Y23: ='Analysis 2 '!N15 -> 19191.1
C24: =Analysis!H21 -> 12 | D24: =Analysis!I21 -> 437 | H24: ='Analysis 2 '!A16 -> 12 | I24: ='Analysis 2 '!B16 -> 97 | N24: ='Analysis 2 '!D17 -> 0 | O24: ='Analysis 2 '!E17 -> 0 | T24: ='Analysis 2 '!J16 -> 260 | U24: ='Analysis 2 '!K16 -> 1744.74 | X24: ='Analysis 2 '!M16 -> Greenwich | Y24: ='Analysis 2 '!N16 -> 18941.52
C25: =Analysis!H22 -> 13 | D25: =Analysis!I22 -> 404 | H25: ='Analysis 2 '!A17 -> 13 | I25: ='Analysis 2 '!B17 -> 94 | N25: ='Analysis 2 '!D18 -> 0 | O25: ='Analysis 2 '!E18 -> 0 | T25: ='Analysis 2 '!J17 -> 237 | U25: ='Analysis 2 '!K17 -> 1743.24 | X25: ='Analysis 2 '!M17 -> Notting Hill | Y25: ='Analysis 2 '!N17 -> 18230.86
C26: =Analysis!H23 -> 14 | D26: =Analysis!I23 -> 440 | H26: ='Analysis 2 '!A18 -> 14 | I26: ='Analysis 2 '!B18 -> 92 | N26: ='Analysis 2 '!D19 -> 0 | O26: ='Analysis 2 '!E19 -> 0
C27: =Analysis!H24 -> 15 | D27: =Analysis!I24 -> 429 | H27: ='Analysis 2 '!A19 -> 15 | I27: ='Analysis 2 '!B19 -> 94
C28: =Analysis!H25 -> 16 | D28: =Analysis!I25 -> 413 | H28: ='Analysis 2 '!A20 -> 16 | I28: ='Analysis 2 '!B20 -> 107
C29: =Analysis!H26 -> 17 | D29: =Analysis!I26 -> 372 | H29: ='Analysis 2 '!A21 -> 17 | I29: ='Analysis 2 '!B21 -> 77
C30: =Analysis!H27 -> 18 | D30: =Analysis!I27 -> 416 | H30: ='Analysis 2 '!A22 -> 18 | I30: ='Analysis 2 '!B22 -> 90
C31: =Analysis!H28 -> 19 | D31: =Analysis!I28 -> 374 | H31: ='Analysis 2 '!A23 -> 19 | I31: ='Analysis 2 '!B23 -> 80 | N31: Time Category | O31: Total Ride Requests
C32: =Analysis!H29 -> 20 | D32: =Analysis!I29 -> 416 | H32: ='Analysis 2 '!A24 -> 20 | I32: ='Analysis 2 '!B24 -> 92 | N32: =Analysis!K9 -> Afternoon | O32: =Analysis!L9 -> 2123 | T32: cancellation reason | U32: %of total cancellation
C33: =Analysis!H30 -> 21 | D33: =Analysis!I30 -> 445 | H33: ='Analysis 2 '!A25 -> 21 | I33: ='Analysis 2 '!B25 -> 88 | N33: =Analysis!K10 -> Evening | O33: =Analysis!L10 -> 2856 | T33: ='Analysis 2 '!H32 -> Not the same car | U33: ='Analysis 2 '!I32 -> 0.13125
C34: =Analysis!H31 -> 22 | D34: =Analysis!I31 -> 424 | H34: ='Analysis 2 '!A26 -> 22 | I34: ='Analysis 2 '!B26 -> 94 | N34: =Analysis!K11 -> Morning | O34: =Analysis!L11 -> 5021 | T34: ='Analysis 2 '!H28 -> Driver was rude | U34: ='Analysis 2 '!I28 -> 0.14776786
C35: =Analysis!H32 -> 23 | D35: =Analysis!I32 -> 409 | H35: ='Analysis 2 '!A27 -> 23 | I35: ='Analysis 2 '!B27 -> 94 | T35: ='Analysis 2 '!H29 -> Change my mind | U35: ='Analysis 2 '!I29 -> 0.14464286
T36: ='Analysis 2 '!H27 -> Driver asked to cancel | U36: ='Analysis 2 '!I27 -> 0.14821429
T37: ='Analysis 2 '!H30 -> Long wait time | U37: ='Analysis 2 '!I30 -> 0.14285714
T38: ='Analysis 2 '!H26 -> Not the same driver | U38: ='Analysis 2 '!I26 -> 0.15223214
T39: ='Analysis 2 '!H31 -> Accidental request | U39: ='Analysis 2 '!I31 -> 0.13303571
C40: Customer ID1 | D40: Rating
C41: ='Analysis 2 '!V3 -> 1930 | D41: ='Analysis 2 '!W3 -> 5 | H41: Customer ID | I41: Rides | N41: Column1 | O41: Column2
C42: ='Analysis 2 '!V4 -> 1829 | D42: ='Analysis 2 '!W4 -> 5 | H42: ='Analysis 2 '!P5 -> 2139 | I42: ='Analysis 2 '!Q5 -> 14 | N42: ='Analysis 2 '!E26 -> Not the same driver | O42: ='Analysis 2 '!F26 -> 341
C43: ='Analysis 2 '!V5 -> 1522 | D43: ='Analysis 2 '!W5 -> 5 | H43: ='Analysis 2 '!P6 -> 2119 | I43: ='Analysis 2 '!Q6 -> 14 | N43: ='Analysis 2 '!E27 -> Driver asked to cancel | O43: ='Analysis 2 '!F27 -> 332
C44: ='Analysis 2 '!V6 -> 1267 | D44: ='Analysis 2 '!W6 -> 5 | H44: ='Analysis 2 '!P7 -> 1619 | I44: ='Analysis 2 '!Q7 -> 14 | N44: ='Analysis 2 '!E28 -> Driver was rude | O44: ='Analysis 2 '!F28 -> 331 | T44: Driver ID | U44: Total Revenue
C45: ='Analysis 2 '!V7 -> 1919 | D45: ='Analysis 2 '!W7 -> 5 | H45: ='Analysis 2 '!P8 -> 1967 | I45: ='Analysis 2 '!Q8 -> 13 | N45: ='Analysis 2 '!E29 -> Change my mind | O45: ='Analysis 2 '!F29 -> 324 | T45: ='Analysis 2 '!G4 -> 225 | U45: ='Analysis 2 '!H4 -> 6186.42
C46: ='Analysis 2 '!V8 -> 1349 | D46: ='Analysis 2 '!W8 -> 5 | H46: ='Analysis 2 '!P9 -> 1407 | I46: ='Analysis 2 '!Q9 -> 13 | N46: ='Analysis 2 '!E30 -> Long wait time | O46: ='Analysis 2 '!F30 -> 320 | T46: ='Analysis 2 '!G5 -> 230 | U46: ='Analysis 2 '!H5 -> 6129.53
C47: ='Analysis 2 '!V9 -> 1161 | D47: ='Analysis 2 '!W9 -> 5 | H47: ='Analysis 2 '!P10 -> 1984 | I47: ='Analysis 2 '!Q10 -> 13 | N47: ='Analysis 2 '!E31 -> Accidental request | O47: ='Analysis 2 '!F31 -> 298 | T47: ='Analysis 2 '!G6 -> 212 | U47: ='Analysis 2 '!H6 -> 5896.54
C48: ='Analysis 2 '!V10 -> 1357 | D48: ='Analysis 2 '!W10 -> 5 | H48: ='Analysis 2 '!P11 -> 1017 | I48: ='Analysis 2 '!Q11 -> 13 | N48: ='Analysis 2 '!E32 -> Not the same car | O48: ='Analysis 2 '!F32 -> 294 | T48: ='Analysis 2 '!G7 -> 258 | U48: ='Analysis 2 '!H7 -> 5781.38
H49: ='Analysis 2 '!P12 -> 1592 | I49: ='Analysis 2 '!Q12 -> 12 | T49: ='Analysis 2 '!G8 -> 256 | U49: ='Analysis 2 '!H8 -> 5705.23
...

Sheet Sheet3
A1: Data returned for Sum of Request_ID, 0, All - All - All (First 1000 rows).
A3: Table2[Request_ID] | B3: Table2[Request_Date] | C3: Table2[Request_Time] | D3: Table2[Hour] | E3: Table2[Time in the Day] | F3: Table2[Column1] | G3: Table2[Pickup_Location] | H3: Table2[Dropoff_Location] | I3: Table2[Ride_Type] | J3: Table2[Driver_ID] | K3: Table2[Ride_Status] | L3: Table2[Fare_GBP] | M3: Table2[Distance_Miles] | N3: Table2[Rating] | O3: Table2[Customer_ID] | P3: Table2[DriversID] | Q3: Table2[Customer_Feedback] | R3: Table2[Cancellation_Reason] | S3: Table2[Driver_Feedback] | T3: Table2[Request_Date (Month)] | U3: Table2[Request_Date (Month Index)]
A4: 99912 | B4: 45787 | C4: 0.0097222222 | D4: 0 | E4: Morning | G4: Greenwich | H4: London Bridge | I4: UberX | J4: 203 | K4: Completed | L4: 8.32 | M4: 8.07 | N4: 1 | O4: 1618 | P4: 223 | Q4: Nice ride | S4: Passenger was calm | T4: May | U4: 5
A5: 99863 | B5: 45673 | C5: 0.022916667 | D5: 0 | E5: Morning | G5: Waterloo | H5: Euston | I5: Uber Comfort | J5: 231 | K5: Cancelled | O5: 1707 | P5: 204 | R5: Not the same driver | T5: Jan | U5: 1
A6: 99604 | B6: 45892 | C6: 0.013194444 | D6: 0 | E6: Morning | G6: Greenwich | H6: Victoria | I6: UberX | J6: 235 | K6: Cancelled | O6: 1999 | P6: 212 | R6: Driver asked to cancel | T6: Aug | U6: 8
A7: 99258 | B7: 45995 | C7: 0.027083333 | D7: 0 | E7: Morning | G7: King'S Cross | H7: Notting Hill | I7: Uber Comfort | J7: 228 | K7: Completed | L7: 29.82 | M7: 17.41 | N7: 1 | O7: 1142 | P7: 250 | Q7: Different driver | S7: Passenger was rude | T7: Dec | U7: 12
A8: 99117 | B8: 45808 | C8: 0 | D8: 0 | E8: Morning | G8: Camden | H8: Stratford | I8: Uber Comfort | J8: 201 | K8: Completed | L8: 74.15 | M8: 3.57 | N8: 5 | O8: 1646 | P8: 230 | Q8: Different driver | S8: Passenger was rude | T8: May | U8: 5
A9: 99017 | B9: 46013 | C9: 0.027083333 | D9: 0 | E9: Morning | G9: Greenwich | H9: Canary Wharf | I9: Uber Comfort | J9: 202 | K9: Completed | L9: 35.8 | M9: 2.91 | N9: 4 | O9: 2036 | P9: 222 | Q9: Different car from app | S9: Passenger was rude | T9: Dec | U9: 12
A10: 98669 | B10: 45875 | C10: 0.03125 | D10: 0 | E10: Morning | G10: Euston | H10: Brixton | I10: UberX | J10: 200 | K10: Cancelled | O10: 1689 | P10: 260 | R10: Change my mind | T10: Aug | U10: 8
A11: 98527 | B11: 45829 | C11: 0.013194444 | D11: 0 | E11: Morning | G11: King'S Cross | H11: Stratford | I11: Uber Comfort | J11: 243 | K11: Completed | L11: 70.49 | M11: 5.55 | N11: 2 | O11: 2100 | P11: 214 | Q11: Driver was rude | S11: Passenger was rude | T11: Jun | U11: 6
A12: 98388 | B12: 45875 | C12: 0.0097222222 | D12: 0 | E12: Morning | G12: Euston | H12: Greenwich | I12: Uber Comfort | J12: 223 | K12: Completed | L12: 49.27 | M12: 6.98 | N12: 4 | O12: 1946 | P12: 215 | Q12: Driver was rude | S12: Passenger was calm | T12: Aug | U12: 8
A13: 98295 | B13: 45947 | C13: 0.033333333 | D13: 0 | E13: Morning | G13: Paddington | H13: Brixton | I13: UberXL | J13: 210 | K13: Completed | L13: 76.18 | M13: 3.68 | N13: 4 | O13: 1781 | P13: 243 | Q13: Different driver | S13: Passenger was calm | T13: Oct | U13: 10
A14: 98173 | B14: 45995 | C14: 0.0027777778 | D14: 0 | E14: Morning | G14: Stratford | H14: Euston | I14: UberXL | J14: 220 | K14: Completed | L14: 4.43 | M14: 3.86 | N14: 2 | O14: 1455 | P14: 255 | Q14: Different car from app | S14: Passenger was calm | T14: Dec | U14: 12
A15: 98048 | B15: 45974 | C15: 0.0048611111 | D15: 0 | E15: Morning | G15: London Bridge | H15: Greenwich | I15: Uber Comfort | J15: 248 | K15: Cancelled | O15: 1275 | P15: 214 | R15: Long wait time | T15: Nov | U15: 11
A16: 97683 | B16: 45949 | C16: 0.0055555556 | D16: 0 | E16: Morning | G16: Euston | H16: Camden | I16: Uber Comfort | J16: 217 | K16: Completed | L16: 19.47 | M16: 15.37 | N16: 1 | O16: 1306 | P16: 217 | Q16: Driver was rude | S16: Passenger was calm | T16: Oct | U16: 10
A17: 97636 | B17: 46000 | C17: 0.0020833333 | D17: 0 | E17: Morning | G17: Paddington | H17: Canary Wharf | I17: UberXL | J17: 249 | K17: Cancelled | O17: 1798 | P17: 214 | R17: Long wait time | T17: Dec | U17: 12
A18: 97131 | B18: 45711 | C18: 0.0041666667 | D18: 0 | E18: Morning | G18: Brixton | H18: King'S Cross | I18: UberXL | J18: 259 | K18: Completed | L18: 77.78 | M18: 14.16 | N18: 3 | O18: 2132 | P18: 222 | Q18: Nice ride | S18: Passenger was calm | T18: Feb | U18: 2
A19: 96898 | B19: 45883 | C19: 0.015277778 | D19: 0 | E19: Morning | G19: Euston | H19: Stratford | I19: UberX | J19: 256 | K19: No Driver | O19: 2012 | P19: 204 | T19: Aug | U19: 8
A20: 96886 | B20: 45854 | C20: 0.034722222 | D20: 0 | E20: Morning | G20: Canary Wharf | H20: King'S Cross | I20: UberX | J20: 204 | K20: Completed | L20: 54.97 | M20: 19.19 | N20: 1 | O20: 1567 | P20: 239 | Q20: Different car from app | S20: Passenger was calm | T20: Jul | U20: 7
A21: 95850 | B21: 45873 | C21: 0.0125 | D21: 0 | E21: Morning | G21: Stratford | H21: King'S Cross | I21: UberXL | J21: 259 | K21: Completed | L21: 15.47 | M21: 7.19 | N21: 3 | O21: 1880 | P21: 225 | Q21: Driver was rude | S21: Passenger was calm | T21: Aug | U21: 8
A22: 95534 | B22: 45694 | C22: 0.014583333 | D22: 0 | E22: Morning | G22: Stratford | H22: Paddington | I22: UberX | J22: 223 | K22: Completed | L22: 73.91 | M22: 5.9 | N22: 5 | O22: 1586 | P22: 253 | Q22: Driver was rude | S22: Passenger was rude | T22: Feb | U22: 2
A23: 95512 | B23: 45702 | C23: 0.034722222 | D23: 0 | E23: Morning | G23: Oxford Circus | H23: Paddington | I23: UberXL | J23: 246 | K23: Cancelled | O23: 1380 | P23: 258 | R23: Change my mind | T23: Feb | U23: 2
A24: 95022 | B24: 45706 | C24: 0.010416667 | D24: 0 | E24: Morning | G24: Shoreditch | H24: Paddington | I24: UberXL | J24: 238 | K24: Completed | L24: 29.45 | M24: 7.8 | N24: 4 | O24: 2006 | P24: 250 | Q24: Different driver | S24: Passenger was rude | T24: Feb | U24: 2
A25: 95008 | B25: 46006 | C25: 0.010416667 | D25: 0 | E25: Morning | G25: Shoreditch | H25: Waterloo | I25: UberXL | J25: 214 | K25: Cancelled | O25: 1098 | P25: 223 | R25: Accidental request | T25: Dec | U25: 12
A26: 94920 | B26: 45667 | C26: 0.013888889 | D26: 0 | E26: Morning | G26: Brixton | H26: Greenwich | I26: Uber Comfort | J26: 208 | K26: Completed | L26: 22.44 | M26: 8.57 | N26: 4 | O26: 1246 | P26: 208 | Q26: Nice ride | S26: Passenger was calm | T26: Jan | U26: 1
A27: 94466 | B27: 45706 | C27: 0.017361111 | D27: 0 | E27: Morning | G27: Waterloo | H27: Notting Hill | I27: UberX | J27: 243 | K27: Completed | L27: 77.37 | M27: 20.96 | N27: 3 | O27: 2077 | P27: 223 | Q27: Nice ride | S27: Passenger was calm | T27: Feb | U27: 2
A28: 94346 | B28: 45935 | C28: 0.026388889 | D28: 0 | E28: Morning | G28: Oxford Circus | H28: Victoria | I28: UberXL | J28: 202 | K28: Completed | L28: 5.03 | M28: 25.04 | N28: 1 | O28: 1648 | P28: 254 | Q28: Driver was rude | S28: Passenger was calm | T28: Oct | U28: 10
A29: 94203 | B29: 45963 | C29: 0.029861111 | D29: 0 | E29: Morning | G29: King'S Cross | H29: Camden | I29: UberXL | J29: 252 | K29: Completed | L29: 34.26 | M29: 5.32 | N29: 3 | O29: 1066 | P29: 253 | Q29: No AC | S29: Passenger was calm | T29: Nov | U29: 11
A30: 93986 | B30: 45727 | C30: 0.0083333333 | D30: 0 | E30: Morning | G30: Camden | H30: Waterloo | I30: Uber Comfort | J30: 239 | K30: Completed | L30: 28.93 | M30: 7.65 | N30: 5 | O30: 1318 | P30: 259 | Q30: Car was bad | S30: Passenger was calm | T30: Mar | U30: 3
A31: 93822 | B31: 46005 | C31: 0.031944444 | D31: 0 | E31: Morning | G31: Waterloo | H31: Canary Wharf | I31: Uber Comfort | J31: 252 | K31: Completed | L31: 67.76 | M31: 25.36 | N31: 5 | O31: 1503 | P31: 222 | Q31: Driver was rude | S31: Passenger was calm | T31: Dec | U31: 12
A32: 93474 | B32: 45934 | C32: 0.033333333 | D32: 0 | E32: Morning | G32: Elephant And Castle | H32: Notting Hill | I32: UberX | J32: 242 | K32: Completed | L32: 46.89 | M32: 6.12 | N32: 1 | O32: 1223 | P32: 225 | Q32: Driver was rude | S32: Passenger was rude | T32: Oct | U32: 10
A33: 93447 | B33: 45760 | C33: 0.00625 | D33: 0 | E33: Morning | G33: Notting Hill | H33: Victoria | I33: Uber Comfort | J33: 212 | K33: Completed | L33: 4.71 | M33: 3.19 | N33: 5 | O33: 1002 | P33: 238 | Q33: Different car from app | S33: Passenger was calm | T33: Apr | U33: 4
A34: 93348 | B34: 45987 | C34: 0.020833333 | D34: 0 | E34: Morning | G34: Paddington | H34: Paddington | I34: Uber Comfort | J34: 235 | K34: Cancelled | O34: 1393 | P34: 233 | R34: Driver asked to cancel | T34: Nov | U34: 11
A35: 93287 | B35: 45724 | C35: 0.0020833333 | D35: 0 | E35: Morning | G35: Brixton | H35: Shoreditch | I35: UberX | J35: 203 | K35: Completed | L35: 32.97 | M35: 13.4 | N35: 2 | O35: 1555 | P35: 258 | Q35: No AC | S35: Passenger was calm | T35: Mar | U35: 3
A36: 93244 | B36: 45934 | C36: 0.039583333 | D36: 0 | E36: Morning | G36: Elephant And Castle | H36: Stratford | I36: UberXL | J36: 252 | K36: Cancelled | O36: 1486 | P36: 204 | R36: Driver was rude | T36: Oct | U36: 10
A37: 93056 | B37: 45939 | C37: 0.016666667 | D37: 0 | E37: Morning | G37: Waterloo | H37: Paddington | I37: Uber Comfort | J37: 254 | K37: Completed | L37: 48.19 | M37: 1.19 | N37: 1 | O37: 1272 | P37: 250 | Q37: Driver was rude | S37: Passenger was rude | T37: Oct | U37: 10
A38: 92749 | B38: 45675 | C38: 0.022916667 | D38: 0 | E38: Morning | G38: Paddington | H38: Notting Hill | I38: Uber Comfort | J38: 241 | K38: Cancelled | O38: 1216 | P38: 225 | R38: Not the same driver | T38: Jan | U38: 1
A39: 92701 | B39: 45915 | C39: 0.024305556 | D39: 0 | E39: Morning | G39: Victoria | H39: Camden | I39: Uber Comfort | J39: 225 | K39: Cancelled | O39: 1639 | P39: 259 | R39: Driver asked to cancel | T39: Sep | U39: 9
A40: 92644 | B40: 45698 | C40: 0.033333333 | D40: 0 | E40: Morning | G40: King'S Cross | H40: Victoria | I40: UberXL | J40: 227 | K40: Completed | L40: 57.59 | M40: 27.34 | N40: 5 | O40: 1402 | P40: 217 | Q40: Car was bad | S40: Passenger was calm | T40: Feb | U40: 2
A41: 92582 | B41: 45935 | C41: 0.01875 | D41: 0 | E41: Morning | G41: Stratford | H41: Shoreditch | I41: UberXL | J41: 225 | K41: Cancelled | O41: 1518 | P41: 242 | R41: Change my mind | T41: Oct | U41: 10
...

Sheet Analysis
A3: Count of Request_ID | B3: Distinct Count of Customer_ID | C3: Distinct Count of DriversID | D3: Average of Rating
A4: 10000 | B4: 1201 | C4: 61 | D4: 2.9909469
A6: Row Labels | B6: Count of Request_ID
A7: Cancelled | B7: 2240
A8: Completed | B8: 6738 | C8: =GETPIVOTDATA("[Measures].[Sum of Revenue]",$A$3)/GETPIVOTDATA("[Measures].[Count of Request_ID]",$A$6,"[Table2].[Ride_Status]","[Table2].[Ride_Status].&[Completed]") -> #REF! | E8: Row Labels | F8: Count of Request_ID | H8: Row Labels | I8: Count of Request_ID | K8: Row Labels | L8: Count of Request_ID
A9: No Driver | B9: 1022 | E9: Jan | F9: 806 | H9: 0 | I9: 405 | K9: Afternoon | L9: 2123
A10: Grand Total | B10: 10000 | E10: Feb | F10: 776 | H10: 1 | I10: 392 | K10: Evening | L10: 2856
E11: Mar | F11: 866 | H11: 2 | I11: 423 | K11: Morning | L11: 5021
A12: Row Labels | B12: Count of Request_ID | E12: Apr | F12: 829 | H12: 3 | I12: 420
A13: Cancelled | B13: 0.224 | E13: May | F13: 783 | H13: 4 | I13: 431
A14: Completed | B14: 0.6738 | E14: Jun | F14: 835 | H14: 5 | I14: 455 | K14: Row Labels | L14: Count of Request_ID
A15: No Driver | B15: 0.1022 | E15: Jul | F15: 891 | H15: 6 | I15: 408 | K15: Afternoon | L15: 2123
E16: Aug | F16: 809 | H16: 7 | I16: 387 | K16: Evening | L16: 2856
A17: Row Labels | B17: Count of Request_ID | E17: Sep | F17: 790 | H17: 8 | I17: 416 | K17: Morning | L17: 5021
A18: Afternoon | B18: 2123 | E18: Oct | F18: 869 | H18: 9 | I18: 427
A19: 12 | B19: 437 | E19: Nov | F19: 872 | H19: 10 | I19: 454
A20: 13 | B20: 404 | E20: Dec | F20: 874 | H20: 11 | I20: 403
A21: 14 | B21: 440 | H21: 12 | I21: 437
A22: 15 | B22: 429 | D22: Row Labels | E22: Count of Request_ID | H22: 13 | I22: 404
A23: 16 | B23: 413 | D23: Victoria | E23: 674 | H23: 14 | I23: 440
A24: Evening | B24: 2856 | D24: Paddington | E24: 682 | H24: 15 | I24: 429 | N24: Count of Request_ID
A25: 17 | B25: 372 | D25: Euston | E25: 682 | H25: 16 | I25: 413 | N25: 10000
A26: 18 | B26: 416 | D26: King'S Cross | E26: 706 | H26: 17 | I26: 372
A27: 19 | B27: 374 | D27: Oxford Circus | E27: 730 | H27: 18 | I27: 416
A28: 20 | B28: 416 | H28: 19 | I28: 374
A29: 21 | B29: 445 | D29: Row Labels | E29: Sum of Fare_GBP | H29: 20 | I29: 416
A30: 22 | B30: 424 | D30: Uber Comfort | E30: 98543.09 | H30: 21 | I30: 445
A31: 23 | B31: 409 | D31: UberXL | E31: 101130.96 | H31: 22 | I31: 424
A32: Morning | B32: 5021 | D32: UberX | E32: 103602.93 | H32: 23 | I32: 409
A33: 0 | B33: 405 | I33: =SUM(I9:I32) -> 10000
A34: 1 | B34: 392
A35: 2 | B35: 423
A36: 3 | B36: 420
A37: 4 | B37: 431
A38: 5 | B38: 455 | D38: Sum of Fare_GBP
A39: 6 | B39: 408 | D39: 303276.98
A40: 7 | B40: 387
A41: 8 | B41: 416
A42: 9 | B42: 427
A43: 10 | B43: 454
...

Sheet Analysis 2 
A1: Ride_Status | B1: Cancelled | D1: Ride_Status | E1: Completed
M2: Row Labels | N2: Sum of Fare_GBP | P2: Ride_Status | Q2: Completed | V2: Row Labels | W2: Average of Rating
A3: Row Labels | B3: Count of Request_ID | D3: Row Labels | E3: Count of Request_ID | G3: Row Labels | H3: Sum of Fare_GBP | M3: Oxford Circus | N3: 22678.96 | S3: Row Labels | T3: Sum of Fare_GBP | V3: 1930 | W3: 5
A4: 0 | B4: 96 | D4: 210 | E4: 136 | G4: 225 | H4: 6186.42 | M4: King'S Cross | N4: 21533.45 | P4: Row Labels | Q4: Count of Fare_GBP | S4: 2119 | T4: 700.04 | V4: 1829 | W4: 5
A5: 1 | B5: 88 | D5: 225 | E5: 128 | G5: 230 | H5: 6129.53 | J5: Row Labels | K5: Sum of Distance_Miles | M5: Euston | N5: 21260.91 | P5: 2139 | Q5: 14 | S5: 1676 | T5: 682.07 | V5: 1522 | W5: 5
A6: 2 | B6: 102 | D6: 234 | E6: 126 | G6: 212 | H6: 5896.54 | J6: 213 | K6: 2138.03 | M6: Camden | N6: 21159.78 | P6: 2119 | Q6: 14 | S6: 1687 | T6: 672.29 | V6: 1267 | W6: 5
A7: 3 | B7: 101 | D7: 256 | E7: 126 | G7: 258 | H7: 5781.38 | J7: 225 | K7: 1896.53 | M7: Victoria | N7: 20845.74 | P7: 1619 | Q7: 14 | S7: 2143 | T7: 649.27 | V7: 1919 | W7: 5
A8: 4 | B8: 98 | D8: 240 | E8: 125 | G8: 256 | H8: 5705.23 | J8: 240 | K8: 1856.26 | M8: London Bridge | N8: 20583.42 | P8: 1967 | Q8: 13 | S8: 1967 | T8: 646.44 | V8: 1349 | W8: 5
A9: 5 | B9: 89 | D9: 211 | E9: 125 | G9: 210 | H9: 5681.57 | J9: 230 | K9: 1837.49 | M9: Paddington | N9: 20397.23 | P9: 1407 | Q9: 13 | S9: 1636 | T9: 628.33 | V9: 1161 | W9: 5
A10: 6 | B10: 98 | D10: 217 | E10: 125 | G10: 237 | H10: 5591.67 | J10: 227 | K10: 1826.38 | M10: Shoreditch | N10: 20079.71 | P10: 1984 | Q10: 13 | S10: 1345 | T10: 618.56 | V10: 1357 | W10: 5
A11: 7 | B11: 96 | D11: 230 | E11: 125 | G11: 216 | H11: 5589.16 | J11: 228 | K11: 1819.84 | M11: Brixton | N11: 19919.85 | P11: 1017 | Q11: 13 | S11: 2139 | T11: 614.47 | V11: Grand Total | W11: 5
A12: 8 | B12: 86 | D12: Grand Total | E12: 1016 | G12: 234 | H12: 5553.4 | J12: 248 | K12: 1796.18 | M12: Stratford | N12: 19631.89 | P12: 1592 | Q12: 12 | S12: Grand Total | T12: 5211.47
A13: 9 | B13: 101 | G13: 218 | H13: 5536.75 | J13: 252 | K13: 1757.24 | M13: Waterloo | N13: 19411.92 | P13: 1345 | Q13: 12
A14: 10 | B14: 105 | G14: Grand Total | H14: 57651.65 | J14: 208 | K14: 1752.89 | M14: Canary Wharf | N14: 19410.64 | P14: 2143 | Q14: 12
A15: 11 | B15: 81 | J15: 236 | K15: 1748.27 | M15: Elephant And Castle | N15: 19191.1 | P15: 2151 | Q15: 12
A16: 12 | B16: 97 | J16: 260 | K16: 1744.74 | M16: Greenwich | N16: 18941.52 | P16: 1266 | Q16: 12
A17: 13 | B17: 94 | J17: 237 | K17: 1743.24 | M17: Notting Hill | N17: 18230.86 | P17: 1669 | Q17: 12
A18: 14 | B18: 92 | J18: Grand Total | K18: 21917.09 | M18: Grand Total | N18: 303276.98 | P18: 1286 | Q18: 12
A19: 15 | B19: 94 | P19: 1687 | Q19: 12
A20: 16 | B20: 107 | P20: 1633 | Q20: 12
A21: 17 | B21: 77 | P21: 1694 | Q21: 12
A22: 18 | B22: 90 | P22: 1636 | Q22: 12
A23: 19 | B23: 80 | P23: Grand Total | Q23: 226
A24: 20 | B24: 92
A25: 21 | B25: 88 | E25: Row Labels | F25: Count of Cancellation_Reason | H25: Row Labels | I25: Count of Cancellation_Reason | L25: Row Labels | M25: Count of Request_ID | P25: Ride_Status | Q25: Completed | T25: Sum of Distance_Miles
A26: 22 | B26: 94 | E26: Not the same driver | F26: 341 | H26: Not the same driver | I26: 0.15223214 | L26: Cancelled | M26: 2240 | T26: 96170.96
A27: 23 | B27: 94 | E27: Driver asked to cancel | F27: 332 | H27: Driver asked to cancel | I27: 0.14821429 | L27: Completed | M27: 6738 | P27: Row Labels | Q27: Count of Ride_Status
A28: Grand Total | B28: 2240 | E28: Driver was rude | F28: 331 | H28: Driver was rude | I28: 0.14776786 | L28: No Driver | M28: 1022 | P28: Afternoon | Q28: 0.21133868
E29: Change my mind | F29: 324 | H29: Change my mind | I29: 0.14464286 | L29: Grand Total | M29: 10000 | P29: Evening | Q29: 0.28940338
E30: Long wait time | F30: 320 | H30: Long wait time | I30: 0.14285714 | L30: Ride_Status | M30: Cancelled | P30: Morning | Q30: 0.49925794
A31: Row Labels | B31: Average of Rating | E31: Accidental request | F31: 298 | H31: Accidental request | I31: 0.13303571 | P31: Grand Total | Q31: 1
A32: 245 | B32: 3.4418605 | E32: Not the same car | F32: 294 | H32: Not the same car | I32: 0.13125 | L32: Row Labels | M32: Count of Ride_Status
A33: 255 | B33: 3.2571429 | E33: Grand Total | F33: 2240 | H33: Grand Total | I33: 1 | L33: UberXL | M33: 767
A34: 237 | B34: 3.2222222 | L34: UberX | M34: 757
A35: 221 | B35: 3.2150538 | L35: Uber Comfort | M35: 716
A36: 256 | B36: 3.2063492 | E36: Ride_Status | F36: Completed | L36: Grand Total | M36: 2240 | N36: =GETPIVOTDATA("[Measures].[Count of Ride_Status]",$L$32)/3 -> 746.66667
A37: Grand Total | B37: 3.259962
E38: Row Labels | F38: Sum of Fare_GBP | G38: Sum of Distance_Miles | H38: Count of Ride_Status
E39: 210 | F39: 5681.57 | G39: 2022.95 | H39: 136
E40: 207 | F40: 5478.66 | G40: 1902.18 | H40: 124 | S40: Ride_Status | T40: Completed
...

Sheet uber_ride_requests_2025 (2)
A1: Request_ID | B1: Request_Date | C1: Request_Time | D1: Hour | E1: Time in the Day | F1: Column1 | G1: Pickup_Location | H1: Dropoff_Location | I1: Ride_Type | J1: Driver_ID | K1: Ride_Status | L1: Fare_GBP | M1: Distance_Miles | N1: Rating | O1: Customer_ID | P1: DriversID | Q1: Customer_Feedback | R1: Cancellation_Reason | S1: Driver_Feedback
A2: 10002 | B2: 45767 | C2: 0.66319444 | D2: 15 | E2: =IF(Table2[[#This Row],[Request_Time]]<TIME(12,0,0),"Morning",IF(Table2[[#This Row],[Request_Time]]<TIME(17,0,0),"Afternoon","Evening")) -> Afternoon | G2: Waterloo | H2: Shoreditch | I2: UberX | J2: 225 | K2: Completed | L2: 57.08 | M2: 7.39 | N2: 1 | O2: 1447 | P2: 254 | Q2: No AC | S2: Passenger was calm
A3: 10007 | B3: 45675 | C3: 0.29861111 | D3: 7 | E3: =IF(Table2[[#This Row],[Request_Time]]<TIME(12,0,0),"Morning",IF(Table2[[#This Row],[Request_Time]]<TIME(17,0,0),"Afternoon","Evening")) -> Morning | G3: Elephant And Castle | H3: Brixton | I3: UberXL | J3: 205 | K3: Completed | L3: 57.97 | M3: 17.13 | N3: 3 | O3: 1900 | P3: 255 | Q3: Driver was rude | S3: Passenger was rude
A4: 10013 | B4: 45814 | C4: 0.1375 | D4: 3 | E4: =IF(Table2[[#This Row],[Request_Time]]<TIME(12,0,0),"Morning",IF(Table2[[#This Row],[Request_Time]]<TIME(17,0,0),"Afternoon","Evening")) -> Morning | G4: Paddington | H4: Waterloo | I4: UberXL | J4: 236 | K4: Completed | L4: 4.17 | M4: 26.83 | N4: 4 | O4: 1770 | P4: 254 | Q4: Different car from app | S4: Passenger was rude
A5: 10021 | B5: 45741 | C5: 0.45694444 | D5: 10 | E5: =IF(Table2[[#This Row],[Request_Time]]<TIME(12,0,0),"Morning",IF(Table2[[#This Row],[Request_Time]]<TIME(17,0,0),"Afternoon","Evening")) -> Morning | G5: Waterloo | H5: Brixton | I5: UberXL | J5: 200 | K5: No Driver | O5: 1063 | P5: 249
A6: 10036 | B6: 45828 | C6: 0.27777778 | D6: 6 | E6: =IF(Table2[[#This Row],[Request_Time]]<TIME(12,0,0),"Morning",IF(Table2[[#This Row],[Request_Time]]<TIME(17,0,0),"Afternoon","Evening")) -> Morning | G6: Waterloo | H6: Euston | I6: UberXL | J6: 250 | K6: Cancelled | O6: 1379 | P6: 206 | R6: Not the same driver
A7: 10041 | B7: 45935 | C7: 0.31458333 | D7: 7 | E7: =IF(Table2[[#This Row],[Request_Time]]<TIME(12,0,0),"Morning",IF(Table2[[#This Row],[Request_Time]]<TIME(17,0,0),"Afternoon","Evening")) -> Morning | G7: Oxford Circus | H7: Euston | I7: UberXL | J7: 202 | K7: No Driver | O7: 1009 | P7: 249
A8: 10049 | B8: 45730 | C8: 0.65 | D8: 15 | E8: =IF(Table2[[#This Row],[Request_Time]]<TIME(12,0,0),"Morning",IF(Table2[[#This Row],[Request_Time]]<TIME(17,0,0),"Afternoon","Evening")) -> Afternoon | G8: Canary Wharf | H8: Greenwich | I8: UberX | J8: 253 | K8: Completed | L8: 53.77 | M8: 3.61 | N8: 4 | O8: 1471 | P8: 217 | Q8: Driver was rude | S8: Passenger was rude
A9: 10050 | B9: 45936 | C9: 0.29583333 | D9: 7 | E9: =IF(Table2[[#This Row],[Request_Time]]<TIME(12,0,0),"Morning",IF(Table2[[#This Row],[Request_Time]]<TIME(17,0,0),"Afternoon","Evening")) -> Morning | G9: London Bridge | H9: Victoria | I9: Uber Comfort | J9: 203 | K9: Completed | L9: 12.11 | M9: 15.95 | N9: 1 | O9: 1298 | P9: 205 | Q9: Different car from app | S9: Passenger was rude
A10: 10085 | B10: 45658 | C10: 0.65208333 | D10: 15 | E10: =IF(Table2[[#This Row],[Request_Time]]<TIME(12,0,0),"Morning",IF(Table2[[#This Row],[Request_Time]]<TIME(17,0,0),"Afternoon","Evening")) -> Afternoon | G10: Shoreditch | H10: Oxford Circus | I10: Uber Comfort | J10: 251 | K10: Cancelled | O10: 1232 | P10: 207 | R10: Change my mind
A11: 10088 | B11: 45911 | C11: 0.99236111 | D11: 23 | E11: =IF(Table2[[#This Row],[Request_Time]]<TIME(12,0,0),"Morning",IF(Table2[[#This Row],[Request_Time]]<TIME(17,0,0),"Afternoon","Evening")) -> Evening | G11: Elephant And Castle | H11: Elephant And Castle | I11: UberX | J11: 201 | K11: Completed | L11: 66.56 | M11: 11.61 | N11: 2 | O11: 1546 | P11: 224 | Q11: Nice ride | S11: Passenger was calm
A12: 10088 | B12: 45728 | C12: 0.10763889 | D12: 2 | E12: =IF(Table2[[#This Row],[Request_Time]]<TIME(12,0,0),"Morning",IF(Table2[[#This Row],[Request_Time]]<TIME(17,0,0),"Afternoon","Evening")) -> Morning | G12: Euston | H12: London Bridge | I12: UberX | J12: 246 | K12: Completed | L12: 14.43 | M12: 6.88 | N12: 2 | O12: 2170 | P12: 234 | Q12: Driver was rude | S12: Passenger was rude
A13: 10098 | B13: 45742 | C13: 0.37638889 | D13: 9 | E13: =IF(Table2[[#This Row],[Request_Time]]<TIME(12,0,0),"Morning",IF(Table2[[#This Row],[Request_Time]]<TIME(17,0,0),"Afternoon","Evening")) -> Morning | G13: Elephant And Castle | H13: Canary Wharf | I13: UberX | J13: 246 | K13: Completed | L13: 49.56 | M13: 12.36 | N13: 2 | O13: 1023 | P13: 210 | Q13: Driver was rude | S13: Passenger was rude
A14: 10100 | B14: 45936 | C14: 0.425 | D14: 10 | E14: =IF(Table2[[#This Row],[Request_Time]]<TIME(12,0,0),"Morning",IF(Table2[[#This Row],[Request_Time]]<TIME(17,0,0),"Afternoon","Evening")) -> Morning | G14: Paddington | H14: Oxford Circus | I14: UberX | J14: 212 | K14: Completed | L14: 17.63 | M14: 17.24 | N14: 5 | O14: 1825 | P14: 205 | Q14: Different car from app | S14: Passenger was calm
A15: 10101 | B15: 45885 | C15: 0.36458333 | D15: 8 | E15: =IF(Table2[[#This Row],[Request_Time]]<TIME(12,0,0),"Morning",IF(Table2[[#This Row],[Request_Time]]<TIME(17,0,0),"Afternoon","Evening")) -> Morning | G15: London Bridge | H15: Brixton | I15: UberXL | J15: 205 | K15: Cancelled | O15: 1124 | P15: 254 | R15: Not the same driver
A16: 10103 | B16: 45891 | C16: 0.091666667 | D16: 2 | E16: =IF(Table2[[#This Row],[Request_Time]]<TIME(12,0,0),"Morning",IF(Table2[[#This Row],[Request_Time]]<TIME(17,0,0),"Afternoon","Evening")) -> Morning | G16: Oxford Circus | H16: Stratford | I16: UberXL | J16: 212 | K16: Completed | L16: 75.79 | M16: 12.92 | N16: 1 | O16: 1598 | P16: 231 | Q16: Car was bad | S16: Passenger was rude
A17: 10106 | B17: 45927 | C17: 0.017361111 | D17: 0 | E17: =IF(Table2[[#This Row],[Request_Time]]<TIME(12,0,0),"Morning",IF(Table2[[#This Row],[Request_Time]]<TIME(17,0,0),"Afternoon","Evening")) -> Morning | G17: Canary Wharf | H17: Euston | I17: UberXL | J17: 257 | K17: No Driver | O17: 2112 | P17: 246
A18: 10124 | B18: 45871 | C18: 0.7375 | D18: 17 | E18: =IF(Table2[[#This Row],[Request_Time]]<TIME(12,0,0),"Morning",IF(Table2[[#This Row],[Request_Time]]<TIME(17,0,0),"Afternoon","Evening")) -> Evening | G18: Oxford Circus | H18: Camden | I18: Uber Comfort | J18: 223 | K18: No Driver | O18: 1085 | P18: 216
A19: 10137 | B19: 45717 | C19: 0.59930556 | D19: 14 | E19: =IF(Table2[[#This Row],[Request_Time]]<TIME(12,0,0),"Morning",IF(Table2[[#This Row],[Request_Time]]<TIME(17,0,0),"Afternoon","Evening")) -> Afternoon | G19: King'S Cross | H19: London Bridge | I19: UberX | J19: 227 | K19: Completed | L19: 23.49 | M19: 2.76 | N19: 4 | O19: 1759 | P19: 240 | Q19: Nice ride | S19: Passenger was rude
A20: 10146 | B20: 45772 | C20: 0.35902778 | D20: 8 | E20: =IF(Table2[[#This Row],[Request_Time]]<TIME(12,0,0),"Morning",IF(Table2[[#This Row],[Request_Time]]<TIME(17,0,0),"Afternoon","Evening")) -> Morning | G20: Camden | H20: Oxford Circus | I20: Uber Comfort | J20: 210 | K20: No Driver | O20: 2105 | P20: 229
A21: 10158 | B21: 45801 | C21: 0.46041667 | D21: 11 | E21: =IF(Table2[[#This Row],[Request_Time]]<TIME(12,0,0),"Morning",IF(Table2[[#This Row],[Request_Time]]<TIME(17,0,0),"Afternoon","Evening")) -> Morning | G21: London Bridge | H21: Greenwich | I21: Uber Comfort | J21: 259 | K21: Completed | L21: 72.45 | M21: 4.56 | N21: 3 | O21: 1294 | P21: 205 | Q21: Driver was rude | S21: Passenger was rude
A22: 10159 | B22: 45683 | C22: 0.41875 | D22: 10 | E22: =IF(Table2[[#This Row],[Request_Time]]<TIME(12,0,0),"Morning",IF(Table2[[#This Row],[Request_Time]]<TIME(17,0,0),"Afternoon","Evening")) -> Morning | G22: Paddington | H22: Victoria | I22: UberX | J22: 222 | K22: Completed | L22: 61.67 | M22: 14.28 | N22: 1 | O22: 1111 | P22: 233 | Q22: No AC | S22: Passenger was calm
A23: 10166 | B23: 45892 | C23: 0.67361111 | D23: 16 | E23: =IF(Table2[[#This Row],[Request_Time]]<TIME(12,0,0),"Morning",IF(Table2[[#This Row],[Request_Time]]<TIME(17,0,0),"Afternoon","Evening")) -> Afternoon | G23: Stratford | H23: London Bridge | I23: Uber Comfort | J23: 202 | K23: Cancelled | O23: 1097 | P23: 217 | R23: Change my mind
A24: 10180 | B24: 45875 | C24: 0.18125 | D24: 4 | E24: =IF(Table2[[#This Row],[Request_Time]]<TIME(12,0,0),"Morning",IF(Table2[[#This Row],[Request_Time]]<TIME(17,0,0),"Afternoon","Evening")) -> Morning | G24: Canary Wharf | H24: Paddington | I24: UberX | J24: 218 | K24: Cancelled | O24: 1179 | P24: 247 | R24: Driver was rude
A25: 10197 | B25: 45774 | C25: 0.30972222 | D25: 7 | E25: =IF(Table2[[#This Row],[Request_Time]]<TIME(12,0,0),"Morning",IF(Table2[[#This Row],[Request_Time]]<TIME(17,0,0),"Afternoon","Evening")) -> Morning | G25: London Bridge | H25: Victoria | I25: UberXL | J25: 256 | K25: Completed | L25: 35.74 | M25: 11.76 | N25: 2 | O25: 1659 | P25: 224 | Q25: Different car from app | S25: Passenger was rude
A26: 10202 | B26: 45864 | C26: 0.61041667 | D26: 14 | E26: =IF(Table2[[#This Row],[Request_Time]]<TIME(12,0,0),"Morning",IF(Table2[[#This Row],[Request_Time]]<TIME(17,0,0),"Afternoon","Evening")) -> Afternoon | G26: London Bridge | H26: Shoreditch | I26: UberXL | J26: 201 | K26: Completed | L26: 14.43 | M26: 13.4 | N26: 1 | O26: 1356 | P26: 220 | Q26: Nice ride | S26: Passenger was calm
A27: 10207 | B27: 45814 | C27: 0.4125 | D27: 9 | E27: =IF(Table2[[#This Row],[Request_Time]]<TIME(12,0,0),"Morning",IF(Table2[[#This Row],[Request_Time]]<TIME(17,0,0),"Afternoon","Evening")) -> Morning | G27: Paddington | H27: Victoria | I27: UberX | J27: 211 | K27: Completed | L27: 59.43 | M27: 2.73 | N27: 2 | O27: 1313 | P27: 235 | Q27: Nice ride | S27: Passenger was calm
A28: 10210 | B28: 45963 | C28: 0.66805556 | D28: 16 | E28: =IF(Table2[[#This Row],[Request_Time]]<TIME(12,0,0),"Morning",IF(Table2[[#This Row],[Request_Time]]<TIME(17,0,0),"Afternoon","Evening")) -> Afternoon | G28: Canary Wharf | H28: Notting Hill | I28: Uber Comfort | J28: 259 | K28: Completed | L28: 69.85 | M28: 1.5 | N28: 5 | O28: 1506 | P28: 202 | Q28: Different car from app | S28: Passenger was calm
A29: 10217 | B29: 45775 | C29: 0.975 | D29: 23 | E29: =IF(Table2[[#This Row],[Request_Time]]<TIME(12,0,0),"Morning",IF(Table2[[#This Row],[Request_Time]]<TIME(17,0,0),"Afternoon","Evening")) -> Evening | G29: Shoreditch | H29: Waterloo | I29: UberXL | J29: 212 | K29: Completed | L29: 21.36 | M29: 17.17 | N29: 4 | O29: 1368 | P29: 232 | Q29: Driver was rude | S29: Passenger was calm
A30: 10224 | B30: 45992 | C30: 0.53541667 | D30: 12 | E30: =IF(Table2[[#This Row],[Request_Time]]<TIME(12,0,0),"Morning",IF(Table2[[#This Row],[Request_Time]]<TIME(17,0,0),"Afternoon","Evening")) -> Afternoon | G30: Waterloo | H30: Victoria | I30: UberX | J30: 203 | K30: Completed | L30: 11.89 | M30: 9.26 | N30: 5 | O30: 2144 | P30: 230 | Q30: Different car from app | S30: Passenger was calm
A31: 10236 | B31: 45714 | C31: 0.98680556 | D31: 23 | E31: =IF(Table2[[#This Row],[Request_Time]]<TIME(12,0,0),"Morning",IF(Table2[[#This Row],[Request_Time]]<TIME(17,0,0),"Afternoon","Evening")) -> Evening | G31: Stratford | H31: Greenwich | I31: UberXL | J31: 221 | K31: Completed | L31: 55.9 | M31: 25.57 | N31: 5 | O31: 2131 | P31: 254 | Q31: Nice ride | S31: Passenger was calm
A32: 10238 | B32: 45900 | C32: 0.015277778 | D32: 0 | E32: =IF(Table2[[#This Row],[Request_Time]]<TIME(12,0,0),"Morning",IF(Table2[[#This Row],[Request_Time]]<TIME(17,0,0),"Afternoon","Evening")) -> Morning | G32: Shoreditch | H32: Notting Hill | I32: UberX | J32: 209 | K32: Completed | L32: 32.65 | M32: 4.73 | N32: 3 | O32: 1768 | P32: 259 | Q32: Car was bad | S32: Passenger was calm
A33: 10245 | B33: 45739 | C33: 0.020138889 | D33: 0 | E33: =IF(Table2[[#This Row],[Request_Time]]<TIME(12,0,0),"Morning",IF(Table2[[#This Row],[Request_Time]]<TIME(17,0,0),"Afternoon","Evening")) -> Morning | G33: Elephant And Castle | H33: Notting Hill | I33: UberX | J33: 247 | K33: Completed | L33: 79.57 | M33: 27.2 | N33: 4 | O33: 2080 | P33: 227 | Q33: Driver was rude | S33: Passenger was rude
A34: 10250 | B34: 45868 | C34: 0.41180556 | D34: 9 | E34: =IF(Table2[[#This Row],[Request_Time]]<TIME(12,0,0),"Morning",IF(Table2[[#This Row],[Request_Time]]<TIME(17,0,0),"Afternoon","Evening")) -> Morning | G34: Elephant And Castle | H34: Greenwich | I34: UberXL | J34: 207 | K34: Completed | L34: 56.62 | M34: 21.63 | N34: 2 | O34: 1197 | P34: 212 | Q34: Different car from app | S34: Passenger was rude
A35: 10262 | B35: 45720 | C35: 0.36805556 | D35: 8 | E35: =IF(Table2[[#This Row],[Request_Time]]<TIME(12,0,0),"Morning",IF(Table2[[#This Row],[Request_Time]]<TIME(17,0,0),"Afternoon","Evening")) -> Morning | G35: Euston | H35: Paddington | I35: UberX | J35: 225 | K35: Completed | L35: 57.28 | M35: 14.3 | N35: 4 | O35: 2083 | P35: 215 | Q35: Different driver | S35: Passenger was rude
A36: 10271 | B36: 46013 | C36: 0.68888889 | D36: 16 | E36: =IF(Table2[[#This Row],[Request_Time]]<TIME(12,0,0),"Morning",IF(Table2[[#This Row],[Request_Time]]<TIME(17,0,0),"Afternoon","Evening")) -> Afternoon | G36: Greenwich | H36: Brixton | I36: Uber Comfort | J36: 209 | K36: Completed | L36: 66.28 | M36: 2.56 | N36: 5 | O36: 1966 | P36: 242 | Q36: Different driver | S36: Passenger was rude
A37: 10272 | B37: 45843 | C37: 0.20208333 | D37: 4 | E37: =IF(Table2[[#This Row],[Request_Time]]<TIME(12,0,0),"Morning",IF(Table2[[#This Row],[Request_Time]]<TIME(17,0,0),"Afternoon","Evening")) -> Morning | G37: King'S Cross | H37: Oxford Circus | I37: UberXL | J37: 240 | K37: Cancelled | O37: 1169 | P37: 221 | R37: Driver asked to cancel
A38: 10274 | B38: 45853 | C38: 0.75555556 | D38: 18 | E38: =IF(Table2[[#This Row],[Request_Time]]<TIME(12,0,0),"Morning",IF(Table2[[#This Row],[Request_Time]]<TIME(17,0,0),"Afternoon","Evening")) -> Evening | G38: Victoria | H38: Canary Wharf | I38: UberX | J38: 240 | K38: Completed | L38: 27.11 | M38: 5.9 | N38: 5 | O38: 1273 | P38: 257 | Q38: Driver was rude | S38: Passenger was calm
A39: 10289 | B39: 45800 | C39: 0.525 | D39: 12 | E39: =IF(Table2[[#This Row],[Request_Time]]<TIME(12,0,0),"Morning",IF(Table2[[#This Row],[Request_Time]]<TIME(17,0,0),"Afternoon","Evening")) -> Afternoon | G39: Brixton | H39: Waterloo | I39: Uber Comfort | J39: 249 | K39: Completed | L39: 55.47 | M39: 5.44 | N39: 2 | O39: 1995 | P39: 202 | Q39: Different driver | S39: Passenger was calm
A40: 10297 | B40: 45860 | C40: 0.875 | D40: 21 | E40: =IF(Table2[[#This Row],[Request_Time]]<TIME(12,0,0),"Morning",IF(Table2[[#This Row],[Request_Time]]<TIME(17,0,0),"Afternoon","Evening")) -> Evening | G40: Euston | H40: Stratford | I40: Uber Comfort | J40: 241 | K40: No Driver | O40: 2071 | P40: 217
...

Sheet RAW DATA
A1: Request_ID | B1: Request_Date | C1: Request_Time | D1: Pickup_Location | E1: Dropoff_Location | F1: Ride_Type | G1: Driver_ID | H1: Ride_Status | I1: Fare_GBP | J1: Distance_Miles | K1: Rating | L1: Customer_ID | M1: DriversID | N1: Customer_Feedback | O1: Cancellation_Reason | P1: Driver_Feedback
A2: 85047 | B2: 45915 | C2: 0.72777778 | D2: cAmDEN | E2: King's Cross | F2: UberX | G2: 225 | H2: Completed | I2: 56.42 | J2: 25.11 | K2: 5 | L2: 1515 | M2: 222 | N2: Different car from app | P2: Passenger was rude
A3: 77316 | B3: 45840 | C3: 0.53472222 | D3: brixton | E3: Waterloo | F3: UberX | G3: 256 | H3: No Driver | L3: 2182 | M3: 219
A4: 76369 | B4: 46021 | C4: 0.52430556 | D4: nOtting hill | E4: Stratford | F4: UberXL | G4: 256 | H4: Completed | I4: 33.45 | J4: 16.61 | K4: 4 | L4: 1468 | M4: 254 | N4: Nice ride | P4: Passenger was rude
A5: 81517 | B5: 45978 | C5: 0.99652778 | D5: PaddinGToN | E5: Euston | F5: UberXL | G5: 223 | H5: Cancelled | L5: 1409 | M5: 216 | O5: Driver was rude
A6: 66915 | B6: 45896 | C6: 0.72708333 | D6: caMdEn | E6: Stratford | F6: UberXL | G6: 253 | H6: Cancelled | L6: 1981 | M6: 260 | O6: Driver was rude
A7: 69143 | B7: 45794 | C7: 0.70833333 | D7: gReEnwich | E7: Euston | F7: UberXL | G7: 244 | H7: Completed | I7: Â£33.98 | J7: 4.52 | K7: 1 | L7: 1276 | M7: 234 | N7: Nice ride | P7: Passenger was calm
A8: 76545 | B8: 45959 | C8: 0.18611111 | D8: LONDON BRIDGE | E8: Oxford Circus | F8: UberXL | G8: 256 | H8: Completed | I8: 81.62 | J8: 2.82 | K8: 2 | L8: 1150 | M8: 203 | N8: Driver was rude | P8: Passenger was rude
A9: 13353 | B9: 45988 | C9: 0.50208333 | D9: CAMDEN | E9: Waterloo | F9: Uber Comfort | G9: 239 | H9: Cancelled | L9: 1349 | M9: 209 | O9: Driver asked to cancel
A10: 35623 | B10: 45763 | C10: 0.61666667 | D10: brixton | E10: ElePhant aND CASTLe | F10: UberXL | G10: 228 | H10: Completed | I10: 54.49 | J10: 20.05 | K10: 5 | L10: 1245 | M10: 233 | N10: Car was bad | P10: Passenger was calm
A11: 10643 | B11: 45798 | C11: 0.13402778 | D11: OXFORD CIRCUS | E11: VICTORIA | F11: Uber Comfort | G11: 250 | H11: Cancelled | L11: 2102 | M11: 213 | O11: Not the same car
A12: 44565 | B12: 45801 | C12: 0.79027778 | D12: OXFORD CIRCUS | E12: Stratford | F12: Uber Comfort | G12: 240 | H12: Completed | I12: 64.85 | J12: 15.98 | K12: 5 | L12: 1217 | M12: 232 | N12: Driver was rude | P12: Passenger was calm
A13: 12022 | B13: 45959 | C13: 0.090277778 | D13: victoria | E13: Euston | F13: UberXL | G13: 220 | H13: Completed | I13: 27.57 | J13: 2.23 | K13: 4 | L13: 1933 | M13: 238 | N13: No AC | P13: Passenger was rude
A14: 75701 | B14: 45972 | C14: 0.053472222 | D14: BRIXTON | E14: Victoria | F14: UberXL | G14: 244 | H14: Completed | I14: 78.9 | J14: 13.22 | K14: 1 | L14: 1676 | M14: 218 | N14: Different driver | P14: Passenger was rude
A15: 86756 | B15: 45720 | C15: 0.42222222 | D15: euston | E15: Oxford Circus | F15: UberX | G15: 239 | H15: Cancelled | L15: 1251 | M15: 207 | O15: Not the same driver
A16: 60345 | B16: 45925 | C16: 0.50347222 | D16: london bridge | E16: Stratford | F16: Uber Comfort | G16: 201 | H16: Completed | I16: 52.35 | J16: 12.18 | K16: 2 | L16: 2108 | M16: 243 | N16: No AC | P16: Passenger was rude
A17: 33501 | B17: 45788 | C17: 0.20972222 | D17: camden | E17: Paddington | F17: UberXL | G17: 240 | H17: Completed | I17: Â£22.49 | J17: 11.99 | K17: 3 | L17: 2065 | M17: 248 | N17: Driver was rude | P17: Passenger was calm
A18: 41825 | B18: 45686 | C18: 0.93541667 | D18: waterloo | E18: Euston | F18: Uber Comfort | G18: 257 | H18: Cancelled | L18: 1817 | M18: 245 | O18: Change my mind
A19: 46144 | B19: 45777 | C19: 0.79861111 | D19: king's cross | E19: Waterloo | F19: Uber Comfort | G19: 237 | H19: No Driver | L19: 1639 | M19: 212
A20: 14916 | B20: 45868 | C20: 0.21805556 | D20: brixton | E20: shoreditch | F20: Uber Comfort | G20: 237 | H20: Completed | I20: Â£43.27 | J20: 26.78 | K20: 5 | L20: 1628 | M20: 236 | N20: Different driver | P20: Passenger was rude
A21: 28598 | B21: 45859 | C21: 0.54097222 | D21: SHOREDITCH | E21: Notting Hill | F21: UberX | G21: 210 | H21: Completed | I21: 47.66 | J21: 18.7 | K21: 5 | L21: 1599 | M21: 218 | N21: Nice ride | P21: Passenger was calm
A22: 65397 | B22: 45840 | C22: 0.19027778 | D22: KiNg's crOSS | E22: KING'S CROSS | F22: Uber Comfort | G22: 219 | H22: Completed | I22: Â£82.79 | J22: 0.76 | K22: 5 | L22: 1240 | M22: 222 | N22: Different driver | P22: Passenger was rude
A23: 19048 | B23: 45913 | C23: 0.17152778 | D23: notting hill | E23: Brixton | F23: UberX | G23: 210 | H23: Completed | I23: Â£49.0 | J23: 22.92 | K23: 5 | L23: 1665 | M23: 227 | N23: No AC | P23: Passenger was calm
A24: 38858 | B24: 45827 | C24: 0.45833333 | D24: elEphANt AND cAsTLE | E24: London Bridge | F24: UberXL | G24: 201 | H24: Completed | I24: 77.48 | J24: 11.58 | K24: 2 | L24: 2125 | M24: 245 | N24: Driver was rude | P24: Passenger was rude
A25: 65631 | B25: 45867 | C25: 0.47847222 | D25: KinG'S cRoSs | E25: Brixton | F25: UberXL | G25: 220 | H25: Completed | I25: 11.7 | J25: 19.15 | K25: 5 | L25: 1036 | M25: 249 | N25: Different car from app | P25: Passenger was calm
A26: 30424 | B26: 45892 | C26: 0.73194444 | D26: king's cross | E26: paddington | F26: Uber Comfort | G26: 208 | H26: Completed | I26: 26.43 | J26: 19.54 | K26: 5 | L26: 1221 | M26: 201 | N26: Nice ride | P26: Passenger was calm
A27: 55030 | B27: 45872 | C27: 0.063194444 | D27: KING'S CROSS | E27: Victoria | F27: Uber Comfort | G27: 231 | H27: Completed | I27: 19.01 | J27: 27.68 | K27: 4 | L27: 1272 | M27: 201 | N27: Different driver | P27: Passenger was rude
A28: 86250 | B28: 45845 | C28: 0.36041667 | D28: VICTORIA | E28: Camden | F28: Uber Comfort | G28: 234 | H28: Completed | I28: 71.76 | J28: 14.59 | K28: 4 | L28: 1611 | M28: 230 | N28: No AC | P28: Passenger was calm
A29: 43749 | B29: 45918 | C29: 0.74236111 | D29: eLEpHANt anD CasTlE | E29: Shoreditch | F29: UberX | G29: 246 | H29: Completed | I29: 52.26 | J29: 10.4 | K29: 1 | L29: 1294 | M29: 208 | N29: Different car from app | P29: Passenger was calm
A30: 46748 | B30: 45994 | C30: 0.81458333 | D30: NOTTING HILL | E30: Shoreditch | F30: UberXL | G30: 208 | H30: Cancelled | L30: 1936 | M30: 210 | O30: Driver asked to cancel
A31: 77446 | B31: 45685 | C31: 0.26388889 | D31: KiNg's CRoss | E31: Oxford Circus | F31: UberXL | G31: 242 | H31: Completed | I31: 59.07 | J31: 25.59 | K31: 1 | L31: 1887 | M31: 212 | N31: No AC | P31: Passenger was calm
A32: 58804 | B32: 45745 | C32: 0.34236111 | D32: sTRatfoRd | E32: Oxford Circus | F32: UberX | G32: 222 | H32: Cancelled | L32: 1323 | M32: 207 | O32: Not the same car
A33: 47632 | B33: 45986 | C33: 0.61597222 | D33: SHOREDITCH | E33: Waterloo | F33: UberX | G33: 206 | H33: Completed | I33: 19.33 | J33: 1.34 | K33: 2 | L33: 1294 | M33: 235 | N33: Different driver | P33: Passenger was rude
A34: 99394 | B34: 45841 | C34: 0.64791667 | D34: OXFORD CIRCUS | E34: Camden | F34: UberX | G34: 252 | H34: Completed | I34: 34.57 | J34: 19.7 | K34: 5 | L34: 1565 | M34: 218 | N34: No AC | P34: Passenger was rude
A35: 80881 | B35: 45960 | C35: 0.059027778 | D35: victoria | E35: Stratford | F35: Uber Comfort | G35: 255 | H35: Completed | I35: 9.69 | J35: 11.12 | K35: 5 | L35: 1522 | M35: 201 | N35: Car was bad | P35: Passenger was rude
A36: 78264 | B36: 45694 | C36: 0.85555556 | D36: oxfORD cIrcUS | E36: Greenwich | F36: UberXL | G36: 230 | H36: No Driver | L36: 2085 | M36: 201
A37: 66585 | B37: 45769 | C37: 0.54652778 | D37: eLePhant And CaSTlE | E37: Victoria | F37: UberX | G37: 245 | H37: Completed | I37: 63.15 | J37: 8.6 | K37: 5 | L37: 2151 | M37: 207 | N37: No AC | P37: Passenger was rude
A38: 71207 | B38: 45939 | C38: 0.94861111 | D38: eLepHaNT AND CAstLe | E38: Canary Wharf | F38: Uber Comfort | G38: 225 | H38: Cancelled | L38: 1950 | M38: 205 | O38: Change my mind
A39: 76171 | B39: 45665 | C39: 0.5875 | D39: NOTTING HILL | E39: Victoria | F39: UberXL | G39: 204 | H39: Completed | I39: Â£35.25 | J39: 5.41 | K39: 2 | L39: 1266 | M39: 260 | N39: Driver was rude | P39: Passenger was calm
A40: 82104 | B40: 45922 | C40: 0.34583333 | D40: oxford circus | E40: London Bridge | F40: Uber Comfort | G40: 236 | H40: Completed | I40: 70.64 | J40: 19.38 | K40: 3 | L40: 1693 | M40: 232 | N40: Driver was rude | P40: Passenger was rude
...

Sheet Busines Questions
B2: Uber Rides Request Dashboard – Business Story
B4: Business Context
B6: Uber operates a ride-hailing service across major UK cities, handling thousands of ride requests every month.
B7: Management wants to understand how customers use the platform, when demand is highest, where rides are concentrated, and what drives revenue.
B8: Build a dashboard that summarizes ride request activity for 2025 using sample data.
B9: It is designed to help business stakeholders make data-driven decisions around driver allocation, pricing strategy, customer experience, and revenue optimization.
B16: Business Area | C16: Business Question | D16: Metric(s) Used | E16: Dashboard Visual | F16: Business Insight / Why It Matters
B17: Demand Overview | C17: How many ride requests were made in the selected period? | D17: Total Ride Requests | E17: KPI Card – Total Ride Requests | F17: Shows overall platform demand and usage level.
B18: Demand Overview | C18: How many customers are actively using the platform? | D18: Total Active Customers | E18: KPI Card – Total Active Customers | F18: Measures customer adoption and engagement.
B19: Demand Overview | C19: How many drivers are available to serve demand? | D19: Total Active Drivers | E19: KPI Card – Total Active Drivers | F19: Helps assess whether driver supply matches demand.
B20: Operations | C20: How many rides were successfully completed? | D20: Completed Rides | E20: KPI Card – Completed Rides | F20: Indicates operational efficiency and service success rate.
B21: Operations | C21: What percentage of ride requests were cancelled or had no driver? | D21: Ride Status % (Completed, Cancelled, No Driver) | E21: Pie Chart – Ride Status | F21: Highlights service reliability and potential driver shortages.
B22: Customer Experience | C22: Are customers generally satisfied with the service? | D22: Average Rating | E22: KPI Card – Average Rating | F22: Tracks customer satisfaction and service quality.
B23: Time Analysis | C23: At what time of day is ride demand highest? | D23: Total Ride Requests by Hour | E23: Line Chart – Peak Hour for Ride Activity | F23: Supports driver scheduling and surge pricing decisions.
B24: Time Analysis | C24: How does ride demand change across months? | D24: Monthly Ride Requests | E24: Line Chart – Ride Requests by Date / Month | F24: Identifies seasonal trends and demand fluctuations.
B25: Location Analysis | C25: Which locations generate the highest ride demand? | D25: Ride Requests by Pickup Location | E25: Bar Chart – Top 5 Pickup Locations | F25: Helps prioritize driver allocation in high-demand areas.
B26: Revenue Analysis | C26: How much total revenue is generated? | D26: Total Revenue | E26: KPI Card – Total Revenue | F26: Measures overall financial performance.
B27: Revenue Analysis | C27: How much revenue is earned per ride on average? | D27: Revenue per Ride | E27: KPI Card – Revenue per Ride | F27: Indicates pricing efficiency and ride value.
... B56: Experience Analysis | C56: Does time of day affect ride success? | D56: Completion Rate by Time of Day | E56: Time Category × Completion % | F56: Improves service planning.
B58: Assignment Rule:
B59: Each student must build at least 5 summary tables and explain one business decision that management can take from each table.

Sheet Dashboard (2)
